[2024-06-15T16:26:19.725+0000] {local_task_job_runner.py:120} INFO - ::group::Pre task execution logs
[2024-06-15T16:26:19.784+0000] {taskinstance.py:2076} INFO - Dependencies all met for dep_context=non-requeueable deps ti=<TaskInstance: twitch_data_pipeline.get_twitch_access_token scheduled__2024-03-04T00:00:00+00:00 [queued]>
[2024-06-15T16:26:19.805+0000] {taskinstance.py:2076} INFO - Dependencies all met for dep_context=requeueable deps ti=<TaskInstance: twitch_data_pipeline.get_twitch_access_token scheduled__2024-03-04T00:00:00+00:00 [queued]>
[2024-06-15T16:26:19.808+0000] {taskinstance.py:2306} INFO - Starting attempt 1 of 2
[2024-06-15T16:26:19.845+0000] {taskinstance.py:2330} INFO - Executing <Task(PythonOperator): get_twitch_access_token> on 2024-03-04 00:00:00+00:00
[2024-06-15T16:26:19.856+0000] {standard_task_runner.py:63} INFO - Started process 2027 to run task
[2024-06-15T16:26:19.866+0000] {standard_task_runner.py:90} INFO - Running: ['***', 'tasks', 'run', 'twitch_data_pipeline', 'get_twitch_access_token', 'scheduled__2024-03-04T00:00:00+00:00', '--job-id', '193', '--raw', '--subdir', 'DAGS_FOLDER/twitch_dag.py', '--cfg-path', '/tmp/tmpjt8b3xtb']
[2024-06-15T16:26:19.879+0000] {standard_task_runner.py:91} INFO - Job 193: Subtask get_twitch_access_token
[2024-06-15T16:26:20.275+0000] {task_command.py:426} INFO - Running <TaskInstance: twitch_data_pipeline.get_twitch_access_token scheduled__2024-03-04T00:00:00+00:00 [running]> on host 842f2a220d8d
[2024-06-15T16:26:28.400+0000] {taskinstance.py:2648} INFO - Exporting env vars: AIRFLOW_CTX_DAG_OWNER='***' AIRFLOW_CTX_DAG_ID='twitch_data_pipeline' AIRFLOW_CTX_TASK_ID='get_twitch_access_token' AIRFLOW_CTX_EXECUTION_DATE='2024-03-04T00:00:00+00:00' AIRFLOW_CTX_TRY_NUMBER='1' AIRFLOW_CTX_DAG_RUN_ID='scheduled__2024-03-04T00:00:00+00:00'
[2024-06-15T16:26:28.958+0000] {taskinstance.py:430} INFO - ::endgroup::
[2024-06-15T16:26:39.264+0000] {taskinstance.py:441} INFO - ::group::Post task execution logs
[2024-06-15T16:26:56.974+0000] {taskinstance.py:2905} ERROR - Task failed with exception
Traceback (most recent call last):
  File "/usr/local/lib/python3.9/site-packages/urllib3/connection.py", line 198, in _new_conn
    sock = connection.create_connection(
  File "/usr/local/lib/python3.9/site-packages/urllib3/util/connection.py", line 60, in create_connection
    for res in socket.getaddrinfo(host, port, family, socket.SOCK_STREAM):
  File "/usr/local/lib/python3.9/socket.py", line 954, in getaddrinfo
    for res in _socket.getaddrinfo(host, port, family, type, proto, flags):
socket.gaierror: [Errno -3] Temporary failure in name resolution

The above exception was the direct cause of the following exception:

Traceback (most recent call last):
  File "/usr/local/lib/python3.9/site-packages/urllib3/connectionpool.py", line 793, in urlopen
    response = self._make_request(
  File "/usr/local/lib/python3.9/site-packages/urllib3/connectionpool.py", line 491, in _make_request
    raise new_e
  File "/usr/local/lib/python3.9/site-packages/urllib3/connectionpool.py", line 467, in _make_request
    self._validate_conn(conn)
  File "/usr/local/lib/python3.9/site-packages/urllib3/connectionpool.py", line 1099, in _validate_conn
    conn.connect()
  File "/usr/local/lib/python3.9/site-packages/urllib3/connection.py", line 616, in connect
    self.sock = sock = self._new_conn()
  File "/usr/local/lib/python3.9/site-packages/urllib3/connection.py", line 205, in _new_conn
    raise NameResolutionError(self.host, self, e) from e
urllib3.exceptions.NameResolutionError: <urllib3.connection.HTTPSConnection object at 0x7fc4bacdeaf0>: Failed to resolve 'id.twitch.tv' ([Errno -3] Temporary failure in name resolution)

The above exception was the direct cause of the following exception:

Traceback (most recent call last):
  File "/usr/local/lib/python3.9/site-packages/requests/adapters.py", line 667, in send
    resp = conn.urlopen(
  File "/usr/local/lib/python3.9/site-packages/urllib3/connectionpool.py", line 847, in urlopen
    retries = retries.increment(
  File "/usr/local/lib/python3.9/site-packages/urllib3/util/retry.py", line 515, in increment
    raise MaxRetryError(_pool, url, reason) from reason  # type: ignore[arg-type]
urllib3.exceptions.MaxRetryError: HTTPSConnectionPool(host='id.twitch.tv', port=443): Max retries exceeded with url: /oauth2/token (Caused by NameResolutionError("<urllib3.connection.HTTPSConnection object at 0x7fc4bacdeaf0>: Failed to resolve 'id.twitch.tv' ([Errno -3] Temporary failure in name resolution)"))

During handling of the above exception, another exception occurred:

Traceback (most recent call last):
  File "/usr/local/lib/python3.9/site-packages/airflow/models/taskinstance.py", line 465, in _execute_task
    result = _execute_callable(context=context, **execute_callable_kwargs)
  File "/usr/local/lib/python3.9/site-packages/airflow/models/taskinstance.py", line 432, in _execute_callable
    return execute_callable(context=context, **execute_callable_kwargs)
  File "/usr/local/lib/python3.9/site-packages/airflow/models/baseoperator.py", line 401, in wrapper
    return func(self, *args, **kwargs)
  File "/usr/local/lib/python3.9/site-packages/airflow/operators/python.py", line 235, in execute
    return_value = self.execute_callable()
  File "/usr/local/lib/python3.9/site-packages/airflow/operators/python.py", line 252, in execute_callable
    return self.python_callable(*self.op_args, **self.op_kwargs)
  File "/opt/airflow/dags/twitch_etl.py", line 33, in obtener_token
    response = requests.post(url, data=params)
  File "/usr/local/lib/python3.9/site-packages/requests/api.py", line 115, in post
    return request("post", url, data=data, json=json, **kwargs)
  File "/usr/local/lib/python3.9/site-packages/requests/api.py", line 59, in request
    return session.request(method=method, url=url, **kwargs)
  File "/usr/local/lib/python3.9/site-packages/requests/sessions.py", line 589, in request
    resp = self.send(prep, **send_kwargs)
  File "/usr/local/lib/python3.9/site-packages/requests/sessions.py", line 703, in send
    r = adapter.send(request, **kwargs)
  File "/usr/local/lib/python3.9/site-packages/requests/adapters.py", line 700, in send
    raise ConnectionError(e, request=request)
requests.exceptions.ConnectionError: HTTPSConnectionPool(host='id.twitch.tv', port=443): Max retries exceeded with url: /oauth2/token (Caused by NameResolutionError("<urllib3.connection.HTTPSConnection object at 0x7fc4bacdeaf0>: Failed to resolve 'id.twitch.tv' ([Errno -3] Temporary failure in name resolution)"))
[2024-06-15T16:26:57.614+0000] {taskinstance.py:1206} INFO - Marking task as UP_FOR_RETRY. dag_id=twitch_data_pipeline, task_id=get_twitch_access_token, run_id=scheduled__2024-03-04T00:00:00+00:00, execution_date=20240304T000000, start_date=20240615T162619, end_date=20240615T162657
[2024-06-15T16:26:57.716+0000] {standard_task_runner.py:110} ERROR - Failed to execute job 193 for task get_twitch_access_token (HTTPSConnectionPool(host='id.twitch.tv', port=443): Max retries exceeded with url: /oauth2/token (Caused by NameResolutionError("<urllib3.connection.HTTPSConnection object at 0x7fc4bacdeaf0>: Failed to resolve 'id.twitch.tv' ([Errno -3] Temporary failure in name resolution)")); 2027)
[2024-06-15T16:26:57.747+0000] {local_task_job_runner.py:240} INFO - Task exited with return code 1
[2024-06-15T16:26:57.882+0000] {taskinstance.py:3503} INFO - 0 downstream tasks scheduled from follow-on schedule check
[2024-06-15T16:26:57.886+0000] {local_task_job_runner.py:222} INFO - ::endgroup::
