[2024-06-15T16:26:19.701+0000] {local_task_job_runner.py:120} INFO - ::group::Pre task execution logs
[2024-06-15T16:26:19.782+0000] {taskinstance.py:2076} INFO - Dependencies all met for dep_context=non-requeueable deps ti=<TaskInstance: twitch_data_pipeline.extract_twitch_data scheduled__2024-03-02T00:00:00+00:00 [queued]>
[2024-06-15T16:26:19.800+0000] {taskinstance.py:2076} INFO - Dependencies all met for dep_context=requeueable deps ti=<TaskInstance: twitch_data_pipeline.extract_twitch_data scheduled__2024-03-02T00:00:00+00:00 [queued]>
[2024-06-15T16:26:19.805+0000] {taskinstance.py:2306} INFO - Starting attempt 1 of 2
[2024-06-15T16:26:19.843+0000] {taskinstance.py:2330} INFO - Executing <Task(PythonOperator): extract_twitch_data> on 2024-03-02 00:00:00+00:00
[2024-06-15T16:26:19.858+0000] {standard_task_runner.py:63} INFO - Started process 2028 to run task
[2024-06-15T16:26:19.865+0000] {standard_task_runner.py:90} INFO - Running: ['***', 'tasks', 'run', 'twitch_data_pipeline', 'extract_twitch_data', 'scheduled__2024-03-02T00:00:00+00:00', '--job-id', '191', '--raw', '--subdir', 'DAGS_FOLDER/twitch_dag.py', '--cfg-path', '/tmp/tmpiu82vloe']
[2024-06-15T16:26:19.874+0000] {standard_task_runner.py:91} INFO - Job 191: Subtask extract_twitch_data
[2024-06-15T16:26:20.278+0000] {task_command.py:426} INFO - Running <TaskInstance: twitch_data_pipeline.extract_twitch_data scheduled__2024-03-02T00:00:00+00:00 [running]> on host 842f2a220d8d
[2024-06-15T16:26:20.716+0000] {taskinstance.py:2648} INFO - Exporting env vars: AIRFLOW_CTX_DAG_OWNER='***' AIRFLOW_CTX_DAG_ID='twitch_data_pipeline' AIRFLOW_CTX_TASK_ID='extract_twitch_data' AIRFLOW_CTX_EXECUTION_DATE='2024-03-02T00:00:00+00:00' AIRFLOW_CTX_TRY_NUMBER='1' AIRFLOW_CTX_DAG_RUN_ID='scheduled__2024-03-02T00:00:00+00:00'
[2024-06-15T16:26:20.855+0000] {taskinstance.py:430} INFO - ::endgroup::
[2024-06-15T16:26:31.042+0000] {taskinstance.py:441} INFO - ::group::Post task execution logs
[2024-06-15T16:26:41.648+0000] {job.py:218} ERROR - Job heartbeat got an exception
Traceback (most recent call last):
  File "/usr/local/lib/python3.9/site-packages/sqlalchemy/engine/base.py", line 3371, in _wrap_pool_connect
    return fn()
  File "/usr/local/lib/python3.9/site-packages/sqlalchemy/pool/base.py", line 327, in connect
    return _ConnectionFairy._checkout(self)
  File "/usr/local/lib/python3.9/site-packages/sqlalchemy/pool/base.py", line 894, in _checkout
    fairy = _ConnectionRecord.checkout(pool)
  File "/usr/local/lib/python3.9/site-packages/sqlalchemy/pool/base.py", line 493, in checkout
    rec = pool._do_get()
  File "/usr/local/lib/python3.9/site-packages/sqlalchemy/pool/impl.py", line 256, in _do_get
    return self._create_connection()
  File "/usr/local/lib/python3.9/site-packages/sqlalchemy/pool/base.py", line 273, in _create_connection
    return _ConnectionRecord(self)
  File "/usr/local/lib/python3.9/site-packages/sqlalchemy/pool/base.py", line 388, in __init__
    self.__connect()
  File "/usr/local/lib/python3.9/site-packages/sqlalchemy/pool/base.py", line 691, in __connect
    pool.logger.debug("Error on connect(): %s", e)
  File "/usr/local/lib/python3.9/site-packages/sqlalchemy/util/langhelpers.py", line 70, in __exit__
    compat.raise_(
  File "/usr/local/lib/python3.9/site-packages/sqlalchemy/util/compat.py", line 211, in raise_
    raise exception
  File "/usr/local/lib/python3.9/site-packages/sqlalchemy/pool/base.py", line 686, in __connect
    self.dbapi_connection = connection = pool._invoke_creator(self)
  File "/usr/local/lib/python3.9/site-packages/sqlalchemy/engine/create.py", line 574, in connect
    return dialect.connect(*cargs, **cparams)
  File "/usr/local/lib/python3.9/site-packages/sqlalchemy/engine/default.py", line 598, in connect
    return self.dbapi.connect(*cargs, **cparams)
  File "/usr/local/lib/python3.9/site-packages/psycopg2/__init__.py", line 122, in connect
    conn = _connect(dsn, connection_factory=connection_factory, **kwasync)
psycopg2.OperationalError: could not translate host name "postgres" to address: Temporary failure in name resolution


The above exception was the direct cause of the following exception:

Traceback (most recent call last):
  File "/usr/local/lib/python3.9/site-packages/airflow/jobs/job.py", line 213, in heartbeat
    heartbeat_callback(session)
  File "/usr/local/lib/python3.9/site-packages/airflow/utils/session.py", line 76, in wrapper
    return func(*args, **kwargs)
  File "/usr/local/lib/python3.9/site-packages/airflow/jobs/local_task_job_runner.py", line 258, in heartbeat_callback
    self.task_instance.refresh_from_db()
  File "/usr/local/lib/python3.9/site-packages/airflow/utils/session.py", line 79, in wrapper
    return func(*args, session=session, **kwargs)
  File "/usr/local/lib/python3.9/site-packages/airflow/models/taskinstance.py", line 1821, in refresh_from_db
    _refresh_from_db(task_instance=self, session=session, lock_for_update=lock_for_update)
  File "/usr/local/lib/python3.9/site-packages/airflow/models/taskinstance.py", line 510, in _refresh_from_db
    ti = TaskInstance.get_task_instance(
  File "/usr/local/lib/python3.9/site-packages/airflow/api_internal/internal_api_call.py", line 115, in wrapper
    return func(*args, **kwargs)
  File "/usr/local/lib/python3.9/site-packages/airflow/utils/session.py", line 76, in wrapper
    return func(*args, **kwargs)
  File "/usr/local/lib/python3.9/site-packages/airflow/models/taskinstance.py", line 1807, in get_task_instance
    return query.one_or_none()
  File "/usr/local/lib/python3.9/site-packages/sqlalchemy/orm/query.py", line 2850, in one_or_none
    return self._iter().one_or_none()
  File "/usr/local/lib/python3.9/site-packages/sqlalchemy/orm/query.py", line 2916, in _iter
    result = self.session.execute(
  File "/usr/local/lib/python3.9/site-packages/sqlalchemy/orm/session.py", line 1716, in execute
    conn = self._connection_for_bind(bind)
  File "/usr/local/lib/python3.9/site-packages/sqlalchemy/orm/session.py", line 1555, in _connection_for_bind
    return self._transaction._connection_for_bind(
  File "/usr/local/lib/python3.9/site-packages/sqlalchemy/orm/session.py", line 750, in _connection_for_bind
    conn = bind.connect()
  File "/usr/local/lib/python3.9/site-packages/sqlalchemy/future/engine.py", line 412, in connect
    return super(Engine, self).connect()
  File "/usr/local/lib/python3.9/site-packages/sqlalchemy/engine/base.py", line 3325, in connect
    return self._connection_cls(self, close_with_result=close_with_result)
  File "/usr/local/lib/python3.9/site-packages/sqlalchemy/engine/base.py", line 96, in __init__
    else engine.raw_connection()
  File "/usr/local/lib/python3.9/site-packages/sqlalchemy/engine/base.py", line 3404, in raw_connection
    return self._wrap_pool_connect(self.pool.connect, _connection)
  File "/usr/local/lib/python3.9/site-packages/sqlalchemy/engine/base.py", line 3374, in _wrap_pool_connect
    Connection._handle_dbapi_exception_noconnection(
  File "/usr/local/lib/python3.9/site-packages/sqlalchemy/engine/base.py", line 2208, in _handle_dbapi_exception_noconnection
    util.raise_(
  File "/usr/local/lib/python3.9/site-packages/sqlalchemy/util/compat.py", line 211, in raise_
    raise exception
  File "/usr/local/lib/python3.9/site-packages/sqlalchemy/engine/base.py", line 3371, in _wrap_pool_connect
    return fn()
  File "/usr/local/lib/python3.9/site-packages/sqlalchemy/pool/base.py", line 327, in connect
    return _ConnectionFairy._checkout(self)
  File "/usr/local/lib/python3.9/site-packages/sqlalchemy/pool/base.py", line 894, in _checkout
    fairy = _ConnectionRecord.checkout(pool)
  File "/usr/local/lib/python3.9/site-packages/sqlalchemy/pool/base.py", line 493, in checkout
    rec = pool._do_get()
  File "/usr/local/lib/python3.9/site-packages/sqlalchemy/pool/impl.py", line 256, in _do_get
    return self._create_connection()
  File "/usr/local/lib/python3.9/site-packages/sqlalchemy/pool/base.py", line 273, in _create_connection
    return _ConnectionRecord(self)
  File "/usr/local/lib/python3.9/site-packages/sqlalchemy/pool/base.py", line 388, in __init__
    self.__connect()
  File "/usr/local/lib/python3.9/site-packages/sqlalchemy/pool/base.py", line 691, in __connect
    pool.logger.debug("Error on connect(): %s", e)
  File "/usr/local/lib/python3.9/site-packages/sqlalchemy/util/langhelpers.py", line 70, in __exit__
    compat.raise_(
  File "/usr/local/lib/python3.9/site-packages/sqlalchemy/util/compat.py", line 211, in raise_
    raise exception
  File "/usr/local/lib/python3.9/site-packages/sqlalchemy/pool/base.py", line 686, in __connect
    self.dbapi_connection = connection = pool._invoke_creator(self)
  File "/usr/local/lib/python3.9/site-packages/sqlalchemy/engine/create.py", line 574, in connect
    return dialect.connect(*cargs, **cparams)
  File "/usr/local/lib/python3.9/site-packages/sqlalchemy/engine/default.py", line 598, in connect
    return self.dbapi.connect(*cargs, **cparams)
  File "/usr/local/lib/python3.9/site-packages/psycopg2/__init__.py", line 122, in connect
    conn = _connect(dsn, connection_factory=connection_factory, **kwasync)
sqlalchemy.exc.OperationalError: (psycopg2.OperationalError) could not translate host name "postgres" to address: Temporary failure in name resolution

(Background on this error at: https://sqlalche.me/e/14/e3q8)
[2024-06-15T16:26:57.045+0000] {job.py:226} ERROR - Job heartbeat failed with error. Scheduler is in unhealthy state
[2024-06-15T16:26:56.974+0000] {taskinstance.py:2905} ERROR - Task failed with exception
Traceback (most recent call last):
  File "/usr/local/lib/python3.9/site-packages/urllib3/connection.py", line 198, in _new_conn
    sock = connection.create_connection(
  File "/usr/local/lib/python3.9/site-packages/urllib3/util/connection.py", line 60, in create_connection
    for res in socket.getaddrinfo(host, port, family, socket.SOCK_STREAM):
  File "/usr/local/lib/python3.9/socket.py", line 954, in getaddrinfo
    for res in _socket.getaddrinfo(host, port, family, type, proto, flags):
socket.gaierror: [Errno -3] Temporary failure in name resolution

The above exception was the direct cause of the following exception:

Traceback (most recent call last):
  File "/usr/local/lib/python3.9/site-packages/urllib3/connectionpool.py", line 793, in urlopen
    response = self._make_request(
  File "/usr/local/lib/python3.9/site-packages/urllib3/connectionpool.py", line 491, in _make_request
    raise new_e
  File "/usr/local/lib/python3.9/site-packages/urllib3/connectionpool.py", line 467, in _make_request
    self._validate_conn(conn)
  File "/usr/local/lib/python3.9/site-packages/urllib3/connectionpool.py", line 1099, in _validate_conn
    conn.connect()
  File "/usr/local/lib/python3.9/site-packages/urllib3/connection.py", line 616, in connect
    self.sock = sock = self._new_conn()
  File "/usr/local/lib/python3.9/site-packages/urllib3/connection.py", line 205, in _new_conn
    raise NameResolutionError(self.host, self, e) from e
urllib3.exceptions.NameResolutionError: <urllib3.connection.HTTPSConnection object at 0x7fc4bacfc730>: Failed to resolve 'id.twitch.tv' ([Errno -3] Temporary failure in name resolution)

The above exception was the direct cause of the following exception:

Traceback (most recent call last):
  File "/usr/local/lib/python3.9/site-packages/requests/adapters.py", line 667, in send
    resp = conn.urlopen(
  File "/usr/local/lib/python3.9/site-packages/urllib3/connectionpool.py", line 847, in urlopen
    retries = retries.increment(
  File "/usr/local/lib/python3.9/site-packages/urllib3/util/retry.py", line 515, in increment
    raise MaxRetryError(_pool, url, reason) from reason  # type: ignore[arg-type]
urllib3.exceptions.MaxRetryError: HTTPSConnectionPool(host='id.twitch.tv', port=443): Max retries exceeded with url: /oauth2/token (Caused by NameResolutionError("<urllib3.connection.HTTPSConnection object at 0x7fc4bacfc730>: Failed to resolve 'id.twitch.tv' ([Errno -3] Temporary failure in name resolution)"))

During handling of the above exception, another exception occurred:

Traceback (most recent call last):
  File "/usr/local/lib/python3.9/site-packages/airflow/models/taskinstance.py", line 465, in _execute_task
    result = _execute_callable(context=context, **execute_callable_kwargs)
  File "/usr/local/lib/python3.9/site-packages/airflow/models/taskinstance.py", line 432, in _execute_callable
    return execute_callable(context=context, **execute_callable_kwargs)
  File "/usr/local/lib/python3.9/site-packages/airflow/models/baseoperator.py", line 401, in wrapper
    return func(self, *args, **kwargs)
  File "/usr/local/lib/python3.9/site-packages/airflow/operators/python.py", line 235, in execute
    return_value = self.execute_callable()
  File "/usr/local/lib/python3.9/site-packages/airflow/operators/python.py", line 252, in execute_callable
    return self.python_callable(*self.op_args, **self.op_kwargs)
  File "/opt/airflow/dags/twitch_etl.py", line 42, in extraer_datos
    access_token = obtener_token()
  File "/opt/airflow/dags/twitch_etl.py", line 33, in obtener_token
    response = requests.post(url, data=params)
  File "/usr/local/lib/python3.9/site-packages/requests/api.py", line 115, in post
    return request("post", url, data=data, json=json, **kwargs)
  File "/usr/local/lib/python3.9/site-packages/requests/api.py", line 59, in request
    return session.request(method=method, url=url, **kwargs)
  File "/usr/local/lib/python3.9/site-packages/requests/sessions.py", line 589, in request
    resp = self.send(prep, **send_kwargs)
  File "/usr/local/lib/python3.9/site-packages/requests/sessions.py", line 703, in send
    r = adapter.send(request, **kwargs)
  File "/usr/local/lib/python3.9/site-packages/requests/adapters.py", line 700, in send
    raise ConnectionError(e, request=request)
requests.exceptions.ConnectionError: HTTPSConnectionPool(host='id.twitch.tv', port=443): Max retries exceeded with url: /oauth2/token (Caused by NameResolutionError("<urllib3.connection.HTTPSConnection object at 0x7fc4bacfc730>: Failed to resolve 'id.twitch.tv' ([Errno -3] Temporary failure in name resolution)"))
[2024-06-15T16:26:57.613+0000] {taskinstance.py:1206} INFO - Marking task as UP_FOR_RETRY. dag_id=twitch_data_pipeline, task_id=extract_twitch_data, run_id=scheduled__2024-03-02T00:00:00+00:00, execution_date=20240302T000000, start_date=20240615T162619, end_date=20240615T162657
[2024-06-15T16:26:57.709+0000] {standard_task_runner.py:110} ERROR - Failed to execute job 191 for task extract_twitch_data (HTTPSConnectionPool(host='id.twitch.tv', port=443): Max retries exceeded with url: /oauth2/token (Caused by NameResolutionError("<urllib3.connection.HTTPSConnection object at 0x7fc4bacfc730>: Failed to resolve 'id.twitch.tv' ([Errno -3] Temporary failure in name resolution)")); 2028)
[2024-06-15T16:26:57.796+0000] {local_task_job_runner.py:240} INFO - Task exited with return code 1
[2024-06-15T16:26:57.864+0000] {taskinstance.py:3503} INFO - 0 downstream tasks scheduled from follow-on schedule check
[2024-06-15T16:26:57.870+0000] {local_task_job_runner.py:222} INFO - ::endgroup::
